<?xml version="1.0" encoding="UTF-8"?>
<!-- Generated by org.testng.reporters.JUnitReportReporter -->
<testsuite hostname="nana-PC" name="NewTest" tests="3" failures="0" timestamp="28 Jun 2017 10:15:05 GMT" time="1.116" errors="1">
  <testcase name="api_test" time="0.049" classname="NewTest"/>
  <testcase name="api_test" time="0.033" classname="NewTest"/>
  <testcase name="api_test" time="1.034" classname="NewTest">
    <error type="java.lang.AssertionError" message="expected:&lt;A new creditcard has been created&gt; but was:&lt;{&quot;status&quot;:409,&quot;code&quot;:409,&quot;message&quot;:&quot;creditcard  number already existing in the database with the id 11&quot;,&quot;link&quot;:&quot;http://www.codingpedia.org/ama/tutorial-rest-api-design-and-implementation-in-java-with-jersey-and-spring/&quot;,&quot;developerMessage&quot;:&quot;Please verify that the number are properly generated&quot;}&gt;">
      <![CDATA[java.lang.AssertionError: expected:<A new creditcard has been created> but was:<{"status":409,"code":409,"message":"creditcard  number already existing in the database with the id 11","link":"http://www.codingpedia.org/ama/tutorial-rest-api-design-and-implementation-in-java-with-jersey-and-spring/","developerMessage":"Please verify that the number are properly generated"}>
	at org.testng.Assert.fail(Assert.java:89)
	at org.testng.Assert.failNotEquals(Assert.java:489)
	at org.testng.Assert.assertEquals(Assert.java:118)
	at org.testng.Assert.assertEquals(Assert.java:171)
	at org.testng.Assert.assertEquals(Assert.java:181)
	at NewTest.api_test(NewTest.java:157)
	at sun.reflect.NativeMethodAccessorImpl.invoke0(Native Method)
	at sun.reflect.NativeMethodAccessorImpl.invoke(NativeMethodAccessorImpl.java:62)
	at sun.reflect.DelegatingMethodAccessorImpl.invoke(DelegatingMethodAccessorImpl.java:43)
	at java.lang.reflect.Method.invoke(Method.java:498)
	at org.testng.internal.MethodInvocationHelper.invokeMethod(MethodInvocationHelper.java:80)
	at org.testng.internal.Invoker.invokeMethod(Invoker.java:673)
	at org.testng.internal.Invoker.invokeTestMethod(Invoker.java:842)
	at org.testng.internal.Invoker.invokeTestMethods(Invoker.java:1166)
	at org.testng.internal.TestMethodWorker.invokeTestMethods(TestMethodWorker.java:125)
	at org.testng.internal.TestMethodWorker.run(TestMethodWorker.java:109)
	at org.testng.TestRunner.runWorkers(TestRunner.java:1178)
	at org.testng.TestRunner.privateRun(TestRunner.java:757)
	at org.testng.TestRunner.run(TestRunner.java:608)
	at org.testng.SuiteRunner.runTest(SuiteRunner.java:334)
	at org.testng.SuiteRunner.runSequentially(SuiteRunner.java:329)
	at org.testng.SuiteRunner.privateRun(SuiteRunner.java:291)
	at org.testng.SuiteRunner.run(SuiteRunner.java:240)
	at org.testng.SuiteRunnerWorker.runSuite(SuiteRunnerWorker.java:52)
	at org.testng.SuiteRunnerWorker.run(SuiteRunnerWorker.java:86)
	at org.testng.TestNG.runSuitesSequentially(TestNG.java:1158)
	at org.testng.TestNG.runSuitesLocally(TestNG.java:1083)
	at org.testng.TestNG.run(TestNG.java:999)
	at org.testng.remote.AbstractRemoteTestNG.run(AbstractRemoteTestNG.java:132)
	at org.testng.remote.RemoteTestNG.initAndRun(RemoteTestNG.java:230)
	at org.testng.remote.RemoteTestNG.main(RemoteTestNG.java:76)
]]>
    </error>
  </testcase>
</testsuite>
